Workbook

Sheet Query_Interface
A1: ChromaCodex Query Interface
A2: Choose filter values below. Use All to include every value. Results appear on Query_Results.
A4: FILTER FIELD | B4: SELECT VALUE | D4: Status / Notes
A5: Brand | B5: All | D5: Dropdown is populated from Query_Filter_Lists, which is rebuilt from live database tables.
A6: Medium | B6: All | D6: Dropdown is populated from Query_Filter_Lists, which is rebuilt from live database tables.
A7: Product Line | B7: All | D7: Dropdown is populated from Query_Filter_Lists, which is rebuilt from live database tables.
A8: Pigment Code | B8: All | D8: Dropdown is populated from Query_Filter_Lists, which is rebuilt from live database tables.
A9: Color Family | B9: All | D9: Dropdown is populated from Query_Filter_Lists, which is rebuilt from live database tables.
A10: Transparency | B10: All | D10: Dropdown is populated from Query_Filter_Lists, which is rebuilt from live database tables.
A11: Permanence | B11: All | D11: Dropdown is populated from Query_Filter_Lists, which is rebuilt from live database tables.
A12: Single Pigment | B12: All | D12: Dropdown is populated from Query_Filter_Lists, which is rebuilt from live database tables.
A14: REPORT OUTPUT
A15: Go to Query_Results to view the filtered report. Query_Source_View contains the helper formulas.
A17: Important
A18: This version uses the Pigments table to populate the Pigment Code dropdown and uses Paint_Pigments to validate paint-pigment links.

Sheet Query_Results
A1: ChromaCodex Query Results
A2: Results update from Query_Interface selections. Use All to include every value.
A4: Matching Record Count | B4: =COUNTIF(Query_Source_View!$Y$2:$Y$1000,1) -> 352
A5: Brand | B5: =Query_Interface!B5 -> All
A6: Medium | B6: =Query_Interface!B6 -> All
A7: Product Line | B7: =Query_Interface!B7 -> All
A8: Pigment Code | B8: =Query_Interface!B8 -> All
A9: Color Family | B9: =Query_Interface!B9 -> All
A10: Transparency | B10: =Query_Interface!B10 -> All
A11: Permanence | B11: =Query_Interface!B11 -> All
A12: Single Pigment | B12: =Query_Interface!B12 -> All
A14: Paint_ID | B14: Brand_Name | C14: Medium | D14: Product_Line_Name | E14: Paint_Name | F14: Color_Family | G14: Pigment_Code | H14: Pigment_Count | I14: Single_Pigment | J14: Transparency | K14: Permanence | L14: ASTM_Rating | M14: WN_Series_Number | N14: Verification_Status | O14: Source_URL
A15: =IFERROR(INDEX(Query_Source_View!$A:$A,MATCH(ROW()-14,Query_Source_View!$Z:$Z,0)),"") -> PNT000001 | B15: =IFERROR(INDEX(Query_Source_View!$D:$D,MATCH(ROW()-14,Query_Source_View!$Z:$Z,0)),"") -> Winsor And Newton | C15: =IFERROR(INDEX(Query_Source_View!$F:$F,MATCH(ROW()-14,Query_Source_View!$Z:$Z,0)),"") -> Oil | D15: =IFERROR(INDEX(Query_Source_View!$H:$H,MATCH(ROW()-14,Query_Source_View!$Z:$Z,0)),"") -> Artists Oil | E15: =IFERROR(INDEX(Query_Source_View!$J:$J,MATCH(ROW()-14,Query_Source_View!$Z:$Z,0)),"") -> Alizarin Crimson | F15: =IFERROR(INDEX(Query_Source_View!$L:$L,MATCH(ROW()-14,Query_Source_View!$Z:$Z,0)),"") -> Red | G15: =IFERROR(INDEX(Query_Source_View!$N:$N,MATCH(ROW()-14,Query_Source_View!$Z:$Z,0)),"") -> PR83 | H15: =IFERROR(INDEX(Query_Source_View!$P:$P,MATCH(ROW()-14,Query_Source_View!$Z:$Z,0)),"") -> 1 | I15: =IFERROR(INDEX(Query_Source_View!$Q:$Q,MATCH(ROW()-14,Query_Source_View!$Z:$Z,0)),"") -> Yes | J15: =IFERROR(INDEX(Query_Source_View!$R:$R,MATCH(ROW()-14,Query_Source_View!$Z:$Z,0)),"") -> 0 | K15: =IFERROR(INDEX(Query_Source_View!$T:$T,MATCH(ROW()-14,Query_Source_View!$Z:$Z,0)),"") -> B | L15: =IFERROR(INDEX(Query_Source_View!$U:$U,MATCH(ROW()-14,Query_Source_View!$Z:$Z,0)),"") -> 0 | M15: =IFERROR(INDEX(Query_Source_View!$V:$V,MATCH(ROW()-14,Query_Source_View!$Z:$Z,0)),"") -> 0 | N15: =IFERROR(INDEX(Query_Source_View!$W:$W,MATCH(ROW()-14,Query_Source_View!$Z:$Z,0)),"") -> Needs Review | O15: =IFERROR(INDEX(Query_Source_View!$X:$X,MATCH(ROW()-14,Query_Source_View!$Z:$Z,0)),"") -> https://sensuallogic.com/artistcolordata
A16: =IFERROR(INDEX(Query_Source_View!$A:$A,MATCH(ROW()-14,Query_Source_View!$Z:$Z,0)),"") -> PNT000002 | B16: =IFERROR(INDEX(Query_Source_View!$D:$D,MATCH(ROW()-14,Query_Source_View!$Z:$Z,0)),"") -> Winsor And Newton | C16: =IFERROR(INDEX(Query_Source_View!$F:$F,MATCH(ROW()-14,Query_Source_View!$Z:$Z,0)),"") -> Oil | D16: =IFERROR(INDEX(Query_Source_View!$H:$H,MATCH(ROW()-14,Query_Source_View!$Z:$Z,0)),"") -> Artists Oil | E16: =IFERROR(INDEX(Query_Source_View!$J:$J,MATCH(ROW()-14,Query_Source_View!$Z:$Z,0)),"") -> Bismuth Yellow | F16: =IFERROR(INDEX(Query_Source_View!$L:$L,MATCH(ROW()-14,Query_Source_View!$Z:$Z,0)),"") -> Yellow | G16: =IFERROR(INDEX(Query_Source_View!$N:$N,MATCH(ROW()-14,Query_Source_View!$Z:$Z,0)),"") -> PY184 | H16: =IFERROR(INDEX(Query_Source_View!$P:$P,MATCH(ROW()-14,Query_Source_View!$Z:$Z,0)),"") -> 1 | I16: =IFERROR(INDEX(Query_Source_View!$Q:$Q,MATCH(ROW()-14,Query_Source_View!$Z:$Z,0)),"") -> Yes | J16: =IFERROR(INDEX(Query_Source_View!$R:$R,MATCH(ROW()-14,Query_Source_View!$Z:$Z,0)),"") -> 0 | K16: =IFERROR(INDEX(Query_Source_View!$T:$T,MATCH(ROW()-14,Query_Source_View!$Z:$Z,0)),"") -> A | L16: =IFERROR(INDEX(Query_Source_View!$U:$U,MATCH(ROW()-14,Query_Source_View!$Z:$Z,0)),"") -> 0 | M16: =IFERROR(INDEX(Query_Source_View!$V:$V,MATCH(ROW()-14,Query_Source_View!$Z:$Z,0)),"") -> 0 | N16: =IFERROR(INDEX(Query_Source_View!$W:$W,MATCH(ROW()-14,Query_Source_View!$Z:$Z,0)),"") -> Needs Review | O16: =IFERROR(INDEX(Query_Source_View!$X:$X,MATCH(ROW()-14,Query_Source_View!$Z:$Z,0)),"") -> https://sensuallogic.com/artistcolordata
A17: =IFERROR(INDEX(Query_Source_View!$A:$A,MATCH(ROW()-14,Query_Source_View!$Z:$Z,0)),"") -> PNT000003 | B17: =IFERROR(INDEX(Query_Source_View!$D:$D,MATCH(ROW()-14,Query_Source_View!$Z:$Z,0)),"") -> Winsor And Newton | C17: =IFERROR(INDEX(Query_Source_View!$F:$F,MATCH(ROW()-14,Query_Source_View!$Z:$Z,0)),"") -> Oil | D17: =IFERROR(INDEX(Query_Source_View!$H:$H,MATCH(ROW()-14,Query_Source_View!$Z:$Z,0)),"") -> Artists Oil | E17: =IFERROR(INDEX(Query_Source_View!$J:$J,MATCH(ROW()-14,Query_Source_View!$Z:$Z,0)),"") -> Bright Red | F17: =IFERROR(INDEX(Query_Source_View!$L:$L,MATCH(ROW()-14,Query_Source_View!$Z:$Z,0)),"") -> Red | G17: =IFERROR(INDEX(Query_Source_View!$N:$N,MATCH(ROW()-14,Query_Source_View!$Z:$Z,0)),"") -> PR | H17: =IFERROR(INDEX(Query_Source_View!$P:$P,MATCH(ROW()-14,Query_Source_View!$Z:$Z,0)),"") -> 1 | I17: =IFERROR(INDEX(Query_Source_View!$Q:$Q,MATCH(ROW()-14,Query_Source_View!$Z:$Z,0)),"") -> Yes | J17: =IFERROR(INDEX(Query_Source_View!$R:$R,MATCH(ROW()-14,Query_Source_View!$Z:$Z,0)),"") -> 0 | K17: =IFERROR(INDEX(Query_Source_View!$T:$T,MATCH(ROW()-14,Query_Source_View!$Z:$Z,0)),"") -> A | L17: =IFERROR(INDEX(Query_Source_View!$U:$U,MATCH(ROW()-14,Query_Source_View!$Z:$Z,0)),"") -> 0 | M17: =IFERROR(INDEX(Query_Source_View!$V:$V,MATCH(ROW()-14,Query_Source_View!$Z:$Z,0)),"") -> 0 | N17: =IFERROR(INDEX(Query_Source_View!$W:$W,MATCH(ROW()-14,Query_Source_View!$Z:$Z,0)),"") -> Needs Review | O17: =IFERROR(INDEX(Query_Source_View!$X:$X,MATCH(ROW()-14,Query_Source_View!$Z:$Z,0)),"") -> https://sensuallogic.com/artistcolordata
A18: =IFERROR(INDEX(Query_Source_View!$A:$A,MATCH(ROW()-14,Query_Source_View!$Z:$Z,0)),"") -> PNT000004 | B18: =IFERROR(INDEX(Query_Source_View!$D:$D,MATCH(ROW()-14,Query_Source_View!$Z:$Z,0)),"") -> Winsor And Newton | C18: =IFERROR(INDEX(Query_Source_View!$F:$F,MATCH(ROW()-14,Query_Source_View!$Z:$Z,0)),"") -> Oil | D18: =IFERROR(INDEX(Query_Source_View!$H:$H,MATCH(ROW()-14,Query_Source_View!$Z:$Z,0)),"") -> Artists Oil | E18: =IFERROR(INDEX(Query_Source_View!$J:$J,MATCH(ROW()-14,Query_Source_View!$Z:$Z,0)),"") -> Burnt Sienna | F18: =IFERROR(INDEX(Query_Source_View!$L:$L,MATCH(ROW()-14,Query_Source_View!$Z:$Z,0)),"") -> Orange | G18: =IFERROR(INDEX(Query_Source_View!$N:$N,MATCH(ROW()-14,Query_Source_View!$Z:$Z,0)),"") -> PR101 | H18: =IFERROR(INDEX(Query_Source_View!$P:$P,MATCH(ROW()-14,Query_Source_View!$Z:$Z,0)),"") -> 1 | I18: =IFERROR(INDEX(Query_Source_View!$Q:$Q,MATCH(ROW()-14,Query_Source_View!$Z:$Z,0)),"") -> Yes | J18: =IFERROR(INDEX(Query_Source_View!$R:$R,MATCH(ROW()-14,Query_Source_View!$Z:$Z,0)),"") -> 0 | K18: =IFERROR(INDEX(Query_Source_View!$T:$T,MATCH(ROW()-14,Query_Source_View!$Z:$Z,0)),"") -> AA | L18: =IFERROR(INDEX(Query_Source_View!$U:$U,MATCH(ROW()-14,Query_Source_View!$Z:$Z,0)),"") -> 0 | M18: =IFERROR(INDEX(Query_Source_View!$V:$V,MATCH(ROW()-14,Query_Source_View!$Z:$Z,0)),"") -> 0 | N18: =IFERROR(INDEX(Query_Source_View!$W:$W,MATCH(ROW()-14,Query_Source_View!$Z:$Z,0)),"") -> Needs Review | O18: =IFERROR(INDEX(Query_Source_View!$X:$X,MATCH(ROW()-14,Query_Source_View!$Z:$Z,0)),"") -> https://sensuallogic.com/artistcolordata
A19: =IFERROR(INDEX(Query_Source_View!$A:$A,MATCH(ROW()-14,Query_Source_View!$Z:$Z,0)),"") -> PNT000005 | B19: =IFERROR(INDEX(Query_Source_View!$D:$D,MATCH(ROW()-14,Query_Source_View!$Z:$Z,0)),"") -> Winsor And Newton | C19: =IFERROR(INDEX(Query_Source_View!$F:$F,MATCH(ROW()-14,Query_Source_View!$Z:$Z,0)),"") -> Oil | D19: =IFERROR(INDEX(Query_Source_View!$H:$H,MATCH(ROW()-14,Query_Source_View!$Z:$Z,0)),"") -> Artists Oil | E19: =IFERROR(INDEX(Query_Source_View!$J:$J,MATCH(ROW()-14,Query_Source_View!$Z:$Z,0)),"") -> Cadmium Lemon | F19: =IFERROR(INDEX(Query_Source_View!$L:$L,MATCH(ROW()-14,Query_Source_View!$Z:$Z,0)),"") -> Yellow | G19: =IFERROR(INDEX(Query_Source_View!$N:$N,MATCH(ROW()-14,Query_Source_View!$Z:$Z,0)),"") -> PY35 | H19: =IFERROR(INDEX(Query_Source_View!$P:$P,MATCH(ROW()-14,Query_Source_View!$Z:$Z,0)),"") -> 1 | I19: =IFERROR(INDEX(Query_Source_View!$Q:$Q,MATCH(ROW()-14,Query_Source_View!$Z:$Z,0)),"") -> Yes | J19: =IFERROR(INDEX(Query_Source_View!$R:$R,MATCH(ROW()-14,Query_Source_View!$Z:$Z,0)),"") -> 0 | K19: =IFERROR(INDEX(Query_Source_View!$T:$T,MATCH(ROW()-14,Query_Source_View!$Z:$Z,0)),"") -> A | L19: =IFERROR(INDEX(Query_Source_View!$U:$U,MATCH(ROW()-14,Query_Source_View!$Z:$Z,0)),"") -> 0 | M19: =IFERROR(INDEX(Query_Source_View!$V:$V,MATCH(ROW()-14,Query_Source_View!$Z:$Z,0)),"") -> 0 | N19: =IFERROR(INDEX(Query_Source_View!$W:$W,MATCH(ROW()-14,Query_Source_View!$Z:$Z,0)),"") -> Needs Review | O19: =IFERROR(INDEX(Query_Source_View!$X:$X,MATCH(ROW()-14,Query_Source_View!$Z:$Z,0)),"") -> https://sensuallogic.com/artistcolordata
A20: =IFERROR(INDEX(Query_Source_View!$A:$A,MATCH(ROW()-14,Query_Source_View!$Z:$Z,0)),"") -> PNT000006 | B20: =IFERROR(INDEX(Query_Source_View!$D:$D,MATCH(ROW()-14,Query_Source_View!$Z:$Z,0)),"") -> Winsor And Newton | C20: =IFERROR(INDEX(Query_Source_View!$F:$F,MATCH(ROW()-14,Query_Source_View!$Z:$Z,0)),"") -> Oil | D20: =IFERROR(INDEX(Query_Source_View!$H:$H,MATCH(ROW()-14,Query_Source_View!$Z:$Z,0)),"") -> Artists Oil | E20: =IFERROR(INDEX(Query_Source_View!$J:$J,MATCH(ROW()-14,Query_Source_View!$Z:$Z,0)),"") -> Cadmium Red | F20: =IFERROR(INDEX(Query_Source_View!$L:$L,MATCH(ROW()-14,Query_Source_View!$Z:$Z,0)),"") -> Red | G20: =IFERROR(INDEX(Query_Source_View!$N:$N,MATCH(ROW()-14,Query_Source_View!$Z:$Z,0)),"") -> PR108 | H20: =IFERROR(INDEX(Query_Source_View!$P:$P,MATCH(ROW()-14,Query_Source_View!$Z:$Z,0)),"") -> 1 | I20: =IFERROR(INDEX(Query_Source_View!$Q:$Q,MATCH(ROW()-14,Query_Source_View!$Z:$Z,0)),"") -> Yes | J20: =IFERROR(INDEX(Query_Source_View!$R:$R,MATCH(ROW()-14,Query_Source_View!$Z:$Z,0)),"") -> 0 | K20: =IFERROR(INDEX(Query_Source_View!$T:$T,MATCH(ROW()-14,Query_Source_View!$Z:$Z,0)),"") -> A | L20: =IFERROR(INDEX(Query_Source_View!$U:$U,MATCH(ROW()-14,Query_Source_View!$Z:$Z,0)),"") -> 0 | M20: =IFERROR(INDEX(Query_Source_View!$V:$V,MATCH(ROW()-14,Query_Source_View!$Z:$Z,0)),"") -> 0 | N20: =IFERROR(INDEX(Query_Source_View!$W:$W,MATCH(ROW()-14,Query_Source_View!$Z:$Z,0)),"") -> Needs Review | O20: =IFERROR(INDEX(Query_Source_View!$X:$X,MATCH(ROW()-14,Query_Source_View!$Z:$Z,0)),"") -> https://sensuallogic.com/artistcolordata
A21: =IFERROR(INDEX(Query_Source_View!$A:$A,MATCH(ROW()-14,Query_Source_View!$Z:$Z,0)),"") -> PNT000007 | B21: =IFERROR(INDEX(Query_Source_View!$D:$D,MATCH(ROW()-14,Query_Source_View!$Z:$Z,0)),"") -> Winsor And Newton | C21: =IFERROR(INDEX(Query_Source_View!$F:$F,MATCH(ROW()-14,Query_Source_View!$Z:$Z,0)),"") -> Oil | D21: =IFERROR(INDEX(Query_Source_View!$H:$H,MATCH(ROW()-14,Query_Source_View!$Z:$Z,0)),"") -> Artists Oil | E21: =IFERROR(INDEX(Query_Source_View!$J:$J,MATCH(ROW()-14,Query_Source_View!$Z:$Z,0)),"") -> Cadmium Yellow | F21: =IFERROR(INDEX(Query_Source_View!$L:$L,MATCH(ROW()-14,Query_Source_View!$Z:$Z,0)),"") -> Yellow | G21: =IFERROR(INDEX(Query_Source_View!$N:$N,MATCH(ROW()-14,Query_Source_View!$Z:$Z,0)),"") -> PY35 | H21: =IFERROR(INDEX(Query_Source_View!$P:$P,MATCH(ROW()-14,Query_Source_View!$Z:$Z,0)),"") -> 1 | I21: =IFERROR(INDEX(Query_Source_View!$Q:$Q,MATCH(ROW()-14,Query_Source_View!$Z:$Z,0)),"") -> Yes | J21: =IFERROR(INDEX(Query_Source_View!$R:$R,MATCH(ROW()-14,Query_Source_View!$Z:$Z,0)),"") -> 0 | K21: =IFERROR(INDEX(Query_Source_View!$T:$T,MATCH(ROW()-14,Query_Source_View!$Z:$Z,0)),"") -> A | L21: =IFERROR(INDEX(Query_Source_View!$U:$U,MATCH(ROW()-14,Query_Source_View!$Z:$Z,0)),"") -> 0 | M21: =IFERROR(INDEX(Query_Source_View!$V:$V,MATCH(ROW()-14,Query_Source_View!$Z:$Z,0)),"") -> 0 | N21: =IFERROR(INDEX(Query_Source_View!$W:$W,MATCH(ROW()-14,Query_Source_View!$Z:$Z,0)),"") -> Needs Review | O21: =IFERROR(INDEX(Query_Source_View!$X:$X,MATCH(ROW()-14,Query_Source_View!$Z:$Z,0)),"") -> https://sensuallogic.com/artistcolordata
A22: =IFERROR(INDEX(Query_Source_View!$A:$A,MATCH(ROW()-14,Query_Source_View!$Z:$Z,0)),"") -> PNT000008 | B22: =IFERROR(INDEX(Query_Source_View!$D:$D,MATCH(ROW()-14,Query_Source_View!$Z:$Z,0)),"") -> Winsor And Newton | C22: =IFERROR(INDEX(Query_Source_View!$F:$F,MATCH(ROW()-14,Query_Source_View!$Z:$Z,0)),"") -> Oil | D22: =IFERROR(INDEX(Query_Source_View!$H:$H,MATCH(ROW()-14,Query_Source_View!$Z:$Z,0)),"") -> Artists Oil | E22: =IFERROR(INDEX(Query_Source_View!$J:$J,MATCH(ROW()-14,Query_Source_View!$Z:$Z,0)),"") -> Cadmium Yellow Deep | F22: =IFERROR(INDEX(Query_Source_View!$L:$L,MATCH(ROW()-14,Query_Source_View!$Z:$Z,0)),"") -> Yellow | G22: =IFERROR(INDEX(Query_Source_View!$N:$N,MATCH(ROW()-14,Query_Source_View!$Z:$Z,0)),"") -> PO20 | H22: =IFERROR(INDEX(Query_Source_View!$P:$P,MATCH(ROW()-14,Query_Source_View!$Z:$Z,0)),"") -> 2 | I22: =IFERROR(INDEX(Query_Source_View!$Q:$Q,MATCH(ROW()-14,Query_Source_View!$Z:$Z,0)),"") -> No | J22: =IFERROR(INDEX(Query_Source_View!$R:$R,MATCH(ROW()-14,Query_Source_View!$Z:$Z,0)),"") -> 0 | K22: =IFERROR(INDEX(Query_Source_View!$T:$T,MATCH(ROW()-14,Query_Source_View!$Z:$Z,0)),"") -> A | L22: =IFERROR(INDEX(Query_Source_View!$U:$U,MATCH(ROW()-14,Query_Source_View!$Z:$Z,0)),"") -> 0 | M22: =IFERROR(INDEX(Query_Source_View!$V:$V,MATCH(ROW()-14,Query_Source_View!$Z:$Z,0)),"") -> 0 | N22: =IFERROR(INDEX(Query_Source_View!$W:$W,MATCH(ROW()-14,Query_Source_View!$Z:$Z,0)),"") -> Needs Review | O22: =IFERROR(INDEX(Query_Source_View!$X:$X,MATCH(ROW()-14,Query_Source_View!$Z:$Z,0)),"") -> https://sensuallogic.com/artistcolordata
A23: =IFERROR(INDEX(Query_Source_View!$A:$A,MATCH(ROW()-14,Query_Source_View!$Z:$Z,0)),"") -> PNT000008 | B23: =IFERROR(INDEX(Query_Source_View!$D:$D,MATCH(ROW()-14,Query_Source_View!$Z:$Z,0)),"") -> Winsor And Newton | C23: =IFERROR(INDEX(Query_Source_View!$F:$F,MATCH(ROW()-14,Query_Source_View!$Z:$Z,0)),"") -> Oil | D23: =IFERROR(INDEX(Query_Source_View!$H:$H,MATCH(ROW()-14,Query_Source_View!$Z:$Z,0)),"") -> Artists Oil | E23: =IFERROR(INDEX(Query_Source_View!$J:$J,MATCH(ROW()-14,Query_Source_View!$Z:$Z,0)),"") -> Cadmium Yellow Deep | F23: =IFERROR(INDEX(Query_Source_View!$L:$L,MATCH(ROW()-14,Query_Source_View!$Z:$Z,0)),"") -> Yellow | G23: =IFERROR(INDEX(Query_Source_View!$N:$N,MATCH(ROW()-14,Query_Source_View!$Z:$Z,0)),"") -> PY35 | H23: =IFERROR(INDEX(Query_Source_View!$P:$P,MATCH(ROW()-14,Query_Source_View!$Z:$Z,0)),"") -> 2 | I23: =IFERROR(INDEX(Query_Source_View!$Q:$Q,MATCH(ROW()-14,Query_Source_View!$Z:$Z,0)),"") -> No | J23: =IFERROR(INDEX(Query_Source_View!$R:$R,MATCH(ROW()-14,Query_Source_View!$Z:$Z,0)),"") -> 0 | K23: =IFERROR(INDEX(Query_Source_View!$T:$T,MATCH(ROW()-14,Query_Source_View!$Z:$Z,0)),"") -> A | L23: =IFERROR(INDEX(Query_Source_View!$U:$U,MATCH(ROW()-14,Query_Source_View!$Z:$Z,0)),"") -> 0 | M23: =IFERROR(INDEX(Query_Source_View!$V:$V,MATCH(ROW()-14,Query_Source_View!$Z:$Z,0)),"") -> 0 | N23: =IFERROR(INDEX(Query_Source_View!$W:$W,MATCH(ROW()-14,Query_Source_View!$Z:$Z,0)),"") -> Needs Review | O23: =IFERROR(INDEX(Query_Source_View!$X:$X,MATCH(ROW()-14,Query_Source_View!$Z:$Z,0)),"") -> https://sensuallogic.com/artistcolordata
A24: =IFERROR(INDEX(Query_Source_View!$A:$A,MATCH(ROW()-14,Query_Source_View!$Z:$Z,0)),"") -> PNT000009 | B24: =IFERROR(INDEX(Query_Source_View!$D:$D,MATCH(ROW()-14,Query_Source_View!$Z:$Z,0)),"") -> Winsor And Newton | C24: =IFERROR(INDEX(Query_Source_View!$F:$F,MATCH(ROW()-14,Query_Source_View!$Z:$Z,0)),"") -> Oil | D24: =IFERROR(INDEX(Query_Source_View!$H:$H,MATCH(ROW()-14,Query_Source_View!$Z:$Z,0)),"") -> Artists Oil | E24: =IFERROR(INDEX(Query_Source_View!$J:$J,MATCH(ROW()-14,Query_Source_View!$Z:$Z,0)),"") -> Cerulean Blue | F24: =IFERROR(INDEX(Query_Source_View!$L:$L,MATCH(ROW()-14,Query_Source_View!$Z:$Z,0)),"") -> Blue | G24: =IFERROR(INDEX(Query_Source_View!$N:$N,MATCH(ROW()-14,Query_Source_View!$Z:$Z,0)),"") -> PB35 | H24: =IFERROR(INDEX(Query_Source_View!$P:$P,MATCH(ROW()-14,Query_Source_View!$Z:$Z,0)),"") -> 1 | I24: =IFERROR(INDEX(Query_Source_View!$Q:$Q,MATCH(ROW()-14,Query_Source_View!$Z:$Z,0)),"") -> Yes | J24: =IFERROR(INDEX(Query_Source_View!$R:$R,MATCH(ROW()-14,Query_Source_View!$Z:$Z,0)),"") -> 0 | K24: =IFERROR(INDEX(Query_Source_View!$T:$T,MATCH(ROW()-14,Query_Source_View!$Z:$Z,0)),"") -> AA | L24: =IFERROR(INDEX(Query_Source_View!$U:$U,MATCH(ROW()-14,Query_Source_View!$Z:$Z,0)),"") -> 0 | M24: =IFERROR(INDEX(Query_Source_View!$V:$V,MATCH(ROW()-14,Query_Source_View!$Z:$Z,0)),"") -> 0 | N24: =IFERROR(INDEX(Query_Source_View!$W:$W,MATCH(ROW()-14,Query_Source_View!$Z:$Z,0)),"") -> Needs Review | O24: =IFERROR(INDEX(Query_Source_View!$X:$X,MATCH(ROW()-14,Query_Source_View!$Z:$Z,0)),"") -> https://sensuallogic.com/artistcolordata
A25: =IFERROR(INDEX(Query_Source_View!$A:$A,MATCH(ROW()-14,Query_Source_View!$Z:$Z,0)),"") -> PNT000010 | B25: =IFERROR(INDEX(Query_Source_View!$D:$D,MATCH(ROW()-14,Query_Source_View!$Z:$Z,0)),"") -> Winsor And Newton | C25: =IFERROR(INDEX(Query_Source_View!$F:$F,MATCH(ROW()-14,Query_Source_View!$Z:$Z,0)),"") -> Oil | D25: =IFERROR(INDEX(Query_Source_View!$H:$H,MATCH(ROW()-14,Query_Source_View!$Z:$Z,0)),"") -> Artists Oil | E25: =IFERROR(INDEX(Query_Source_View!$J:$J,MATCH(ROW()-14,Query_Source_View!$Z:$Z,0)),"") -> Cobalt Blue | F25: =IFERROR(INDEX(Query_Source_View!$L:$L,MATCH(ROW()-14,Query_Source_View!$Z:$Z,0)),"") -> Blue | G25: =IFERROR(INDEX(Query_Source_View!$N:$N,MATCH(ROW()-14,Query_Source_View!$Z:$Z,0)),"") -> PB28 | H25: =IFERROR(INDEX(Query_Source_View!$P:$P,MATCH(ROW()-14,Query_Source_View!$Z:$Z,0)),"") -> 1 | I25: =IFERROR(INDEX(Query_Source_View!$Q:$Q,MATCH(ROW()-14,Query_Source_View!$Z:$Z,0)),"") -> Yes | J25: =IFERROR(INDEX(Query_Source_View!$R:$R,MATCH(ROW()-14,Query_Source_View!$Z:$Z,0)),"") -> 0 | K25: =IFERROR(INDEX(Query_Source_View!$T:$T,MATCH(ROW()-14,Query_Source_View!$Z:$Z,0)),"") -> AA | L25: =IFERROR(INDEX(Query_Source_View!$U:$U,MATCH(ROW()-14,Query_Source_View!$Z:$Z,0)),"") -> 0 | M25: =IFERROR(INDEX(Query_Source_View!$V:$V,MATCH(ROW()-14,Query_Source_View!$Z:$Z,0)),"") -> 0 | N25: =IFERROR(INDEX(Query_Source_View!$W:$W,MATCH(ROW()-14,Query_Source_View!$Z:$Z,0)),"") -> Needs Review | O25: =IFERROR(INDEX(Query_Source_View!$X:$X,MATCH(ROW()-14,Query_Source_View!$Z:$Z,0)),"") -> https://sensuallogic.com/artistcolordata
A26: =IFERROR(INDEX(Query_Source_View!$A:$A,MATCH(ROW()-14,Query_Source_View!$Z:$Z,0)),"") -> PNT000011 | B26: =IFERROR(INDEX(Query_Source_View!$D:$D,MATCH(ROW()-14,Query_Source_View!$Z:$Z,0)),"") -> Winsor And Newton | C26: =IFERROR(INDEX(Query_Source_View!$F:$F,MATCH(ROW()-14,Query_Source_View!$Z:$Z,0)),"") -> Oil | D26: =IFERROR(INDEX(Query_Source_View!$H:$H,MATCH(ROW()-14,Query_Source_View!$Z:$Z,0)),"") -> Artists Oil | E26: =IFERROR(INDEX(Query_Source_View!$J:$J,MATCH(ROW()-14,Query_Source_View!$Z:$Z,0)),"") -> Cobalt Blue Deep | F26: =IFERROR(INDEX(Query_Source_View!$L:$L,MATCH(ROW()-14,Query_Source_View!$Z:$Z,0)),"") -> Blue | G26: =IFERROR(INDEX(Query_Source_View!$N:$N,MATCH(ROW()-14,Query_Source_View!$Z:$Z,0)),"") -> PB74 | H26: =IFERROR(INDEX(Query_Source_View!$P:$P,MATCH(ROW()-14,Query_Source_View!$Z:$Z,0)),"") -> 1 | I26: =IFERROR(INDEX(Query_Source_View!$Q:$Q,MATCH(ROW()-14,Query_Source_View!$Z:$Z,0)),"") -> Yes | J26: =IFERROR(INDEX(Query_Source_View!$R:$R,MATCH(ROW()-14,Query_Source_View!$Z:$Z,0)),"") -> 0 | K26: =IFERROR(INDEX(Query_Source_View!$T:$T,MATCH(ROW()-14,Query_Source_View!$Z:$Z,0)),"") -> AA | L26: =IFERROR(INDEX(Query_Source_View!$U:$U,MATCH(ROW()-14,Query_Source_View!$Z:$Z,0)),"") -> 0 | M26: =IFERROR(INDEX(Query_Source_View!$V:$V,MATCH(ROW()-14,Query_Source_View!$Z:$Z,0)),"") -> 0 | N26: =IFERROR(INDEX(Query_Source_View!$W:$W,MATCH(ROW()-14,Query_Source_View!$Z:$Z,0)),"") -> Needs Review | O26: =IFERROR(INDEX(Query_Source_View!$X:$X,MATCH(ROW()-14,Query_Source_View!$Z:$Z,0)),"") -> https://sensuallogic.com/artistcolordata
... A514: =IFERROR(INDEX(Query_Source_View!$A:$A,MATCH(ROW()-14,Query_Source_View!$Z:$Z,0)),"") | B514: =IFERROR(INDEX(Query_Source_View!$D:$D,MATCH(ROW()-14,Query_Source_View!$Z:$Z,0)),"") | C514: =IFERROR(INDEX(Query_Source_View!$F:$F,MATCH(ROW()-14,Query_Source_View!$Z:$Z,0)),"") | D514: =IFERROR(INDEX(Query_Source_View!$H:$H,MATCH(ROW()-14,Query_Source_View!$Z:$Z,0)),"") | E514: =IFERROR(INDEX(Query_Source_View!$J:$J,MATCH(ROW()-14,Query_Source_View!$Z:$Z,0)),"") | F514: =IFERROR(INDEX(Query_Source_View!$L:$L,MATCH(ROW()-14,Query_Source_View!$Z:$Z,0)),"") | G514: =IFERROR(INDEX(Query_Source_View!$N:$N,MATCH(ROW()-14,Query_Source_View!$Z:$Z,0)),"") | H514: =IFERROR(INDEX(Query_Source_View!$P:$P,MATCH(ROW()-14,Query_Source_View!$Z:$Z,0)),"") | I514: =IFERROR(INDEX(Query_Source_View!$Q:$Q,MATCH(ROW()-14,Query_Source_View!$Z:$Z,0)),"") | J514: =IFERROR(INDEX(Query_Source_View!$R:$R,MATCH(ROW()-14,Query_Source_View!$Z:$Z,0)),"") | K514: =IFERROR(INDEX(Query_Source_View!$T:$T,MATCH(ROW()-14,Query_Source_View!$Z:$Z,0)),"") | L514: =IFERROR(INDEX(Query_Source_View!$U:$U,MATCH(ROW()-14,Query_Source_View!$Z:$Z,0)),"") | M514: =IFERROR(INDEX(Query_Source_View!$V:$V,MATCH(ROW()-14,Query_Source_View!$Z:$Z,0)),"") | N514: =IFERROR(INDEX(Query_Source_View!$W:$W,MATCH(ROW()-14,Query_Source_View!$Z:$Z,0)),"") | O514: =IFERROR(INDEX(Query_Source_View!$X:$X,MATCH(ROW()-14,Query_Source_View!$Z:$Z,0)),"")

Sheet Query_Filter_Lists
A1: Brand | B1: Medium | C1: Product Line | D1: Pigment Code | E1: Color Family | F1: Transparency | G1: Permanence | H1: Single Pigment
A2: All | B2: All | C2: All | D2: All | E2: All | F2: All | G2: All | H2: All
A3: Winsor And Newton | B3: Acrylic | C3: Artists Oil | D3: NBr8 | E3: Black Or Gray | F3: Opaque | G3: A | H3: No
B4: Gouache | C4: Designers Gouache | D4: NR9 | E4: Blue | F4: Semi Opaque | G4: AA | H4: Not Applicable
B5: Oil | C5: Galeria Acrylic | D5: PB15 | E5: Earth | F5: Semi Transparent | G5: B | H5: Unknown
C6: Professional Acrylic | D6: PB15:1 | E6: Green | F6: Transparent | G6: C | H6: Yes
D7: PB15:3 | E7: Metallic | G7: Extremely Permanent
D8: PB16 | E8: Orange | G8: Permanent
D9: PB27 | E9: Red
D10: PB28 | E10: Violet
D11: PB29 | E11: White
D12: PB35 | E12: Yellow
D13: PB36
D14: PB60
D15: PB73
D16: PB74
D17: PBk1
D18: PBk10
D19: PBk11
D20: PBk19
D21: PBk31
D22: PBk6
D23: PBk7
D24: PBk9
... D86: Not Provided By Source

Sheet Dashboard
A1: ChromaCodex Database v2
A3: Current Version Purpose | B3: Adds relational IDs and linked entity tables so future query/report logic can be built properly.
A5: New in v2 | B5: Paint_ID, Pigment_ID structure, Measurement_ID, Source_ID, Paint_Pigments join table, Paint_Behavior table, ID crosswalk, relationship map.
A7: Query Readiness | B7: Relational structure is ready. Full interactive reports/dashboards still need to be built in a later version.
A9: Current Imported Dataset | B9: Winsor And Newton Professional Acrylic rows from Sensual Logic Artist Color Data. Source did not provide pigment code, opacity, or permanence in the imported table rows.
A11: File Naming Convention | B11: Use ChromaCodex-Database-v1, ChromaCodex-Database-v2, etc. for future database versions.
A13: Key Sheets
A14: Master_Paint_Records | B14: Actual paint product records with corrected relational fields.
A15: Brands | B15: Brand-level entities.
A16: Mediums | B16: Medium-level entities such as Acrylic, Watercolor, Oil.
A17: Product_Lines_Formulations | B17: Brand + medium + product line/formulation records.
A18: Product_Line_Attributes | B18: Attributes that belong to a formulation/product line.
A19: Brand_Specific_Attributes | B19: Flexible brand-unique attributes.
A20: Schema_Overview | B20: Plain-English explanation of the corrected relational structure.
A21: Raw_Import_Staging | B21: Raw source data preserved before normalization.
A23: Current query interface: Query_Interface
A24: Current query output: Query_Results
A25: Use Query_Source_View or Query_Output filters to query by Pigment_Code, Product_Line, Medium, Transparency, Permanence, ASTM, and Single_Pigment.

Sheet Query_Dashboard_v8
A1: ChromaCodex Database v8 - Query Dashboard
A3: Select filters below. Leave any field as All. Results appear on Query_Output.
A5: Brand | B5: All | D5: Matching records
A6: Medium | B6: All
A7: Product Line | B7: All | D7: Source note | E7: Winsor And Newton official chart rows have WN colour codes but no Color Index pigment codes in the PDF.
A8: Product Line Type | B8: All
A9: Pigment Code | B9: All
A10: Color Family | B10: All
A11: Opacity Code | B11: All
A12: Permanence | B12: All
A13: Verification Status | B13: All

Sheet Query_Dashboard_v6
A1: ChromaCodex Database v6 - Working Query Dashboard
A3: Select filters below. Leave any field as All. Results appear on Query_Output.
A5: Brand | B5: All | C5: Field: Brand_Name | E5: Matching Records
A6: Medium | B6: All | C6: Field: Medium
A7: Product Line | B7: All | C7: Field: Product_Line_Name | E7: Open Query_Output to view results.
A8: Product Line Type | B8: All | C8: Field: Product_Line_Type | E8: All original v3 repaired sheets are preserved.
A9: Pigment Code | B9: All | C9: Field: Pigment_Code | E9: This uses standard INDEX/MATCH helper formulas, not FILTER().
A10: Color Family | B10: All | C10: Field: Color_Family
A11: Transparency | B11: All | C11: Field: Transparency
A12: Granulation | B12: All | C12: Field: Granulation
A13: Staining | B13: All | C13: Field: Staining
A14: Verification Status | B14: All | C14: Field: Verification_Status

Sheet Query_Output
A1: Query Output / Report View
A2: This workbook avoids formulas that can trigger Excel repair errors. Use filter arrows on Query_Source_View or Query_Filterable_View. Pigment Code filters now come from the real Pigments table and Paint_Pigments relationships.
A4: Paint_ID | B4: Brand_Name | C4: Medium | D4: Product_Line_Name | E4: Paint_Name | F4: Color_Family | G4: Pigment_Code | H4: Pigment_Count | I4: Single_Pigment | J4: Transparency | K4: Opacity_Code | L4: Permanence | M4: ASTM_Rating | N4: WN_Series_Number | O4: Verification_Status
A5: PNT000001 | B5: Winsor And Newton | C5: Oil | D5: Artists Oil | E5: Alizarin Crimson | F5: Red | G5: PR83 | H5: 1 | I5: Yes | K5: T | L5: B | O5: Needs Review
A6: PNT000002 | B6: Winsor And Newton | C6: Oil | D6: Artists Oil | E6: Bismuth Yellow | F6: Yellow | G6: PY184 | H6: 1 | I6: Yes | K6: O | L6: A | O6: Needs Review
A7: PNT000003 | B7: Winsor And Newton | C7: Oil | D7: Artists Oil | E7: Bright Red | F7: Red | G7: PR | H7: 1 | I7: Yes | K7: T | L7: A | O7: Needs Review
A8: PNT000004 | B8: Winsor And Newton | C8: Oil | D8: Artists Oil | E8: Burnt Sienna | F8: Orange | G8: PR101 | H8: 1 | I8: Yes | K8: T | L8: AA | O8: Needs Review
A9: PNT000005 | B9: Winsor And Newton | C9: Oil | D9: Artists Oil | E9: Cadmium Lemon | F9: Yellow | G9: PY35 | H9: 1 | I9: Yes | K9: O | L9: A | O9: Needs Review
A10: PNT000006 | B10: Winsor And Newton | C10: Oil | D10: Artists Oil | E10: Cadmium Red | F10: Red | G10: PR108 | H10: 1 | I10: Yes | K10: O | L10: A | O10: Needs Review
A11: PNT000007 | B11: Winsor And Newton | C11: Oil | D11: Artists Oil | E11: Cadmium Yellow | F11: Yellow | G11: PY35 | H11: 1 | I11: Yes | K11: O | L11: A | O11: Needs Review
A12: PNT000008 | B12: Winsor And Newton | C12: Oil | D12: Artists Oil | E12: Cadmium Yellow Deep | F12: Yellow | G12: PO20 | H12: 2 | I12: No | K12: O | L12: A | O12: Needs Review
A13: PNT000008 | B13: Winsor And Newton | C13: Oil | D13: Artists Oil | E13: Cadmium Yellow Deep | F13: Yellow | G13: PY35 | H13: 2 | I13: No | K13: O | L13: A | O13: Needs Review
A14: PNT000009 | B14: Winsor And Newton | C14: Oil | D14: Artists Oil | E14: Cerulean Blue | F14: Blue | G14: PB35 | H14: 1 | I14: Yes | K14: SO | L14: AA | O14: Needs Review
A15: PNT000010 | B15: Winsor And Newton | C15: Oil | D15: Artists Oil | E15: Cobalt Blue | F15: Blue | G15: PB28 | H15: 1 | I15: Yes | K15: ST | L15: AA | O15: Needs Review
A16: PNT000011 | B16: Winsor And Newton | C16: Oil | D16: Artists Oil | E16: Cobalt Blue Deep | F16: Blue | G16: PB74 | H16: 1 | I16: Yes | K16: ST | L16: AA | O16: Needs Review
... A189: PNT000139 | B189: Winsor And Newton | C189: Acrylic | D189: Galeria Acrylic | E189: Yellow Ochre | F189: Yellow | G189: PBk11 | H189: 3 | I189: No | K189: O | L189: AA | O189: Needs Review
A190: PNT000140 | B190: Winsor And Newton | C190: Acrylic | D190: Professional Acrylic | E190: Azo Yellow Medium | F190: Yellow | G190: PY74 | H190: 1 | I190: Yes | J190: Semi Opaque | K190: SO | L190: Permanent | M190: I | N190: 2 | O190: Verified From Official Source
A191: PNT000141 | B191: Winsor And Newton | C191: Acrylic | D191: Professional Acrylic | E191: Bismuth Yellow | F191: Yellow | G191: PY184 | H191: 1 | I191: Yes | J191: Opaque | K191: O | L191: Permanent | M191: I | N191: 4 | O191: Verified From Official Source
A192: PNT000142 | B192: Winsor And Newton | C192: Acrylic | D192: Professional Acrylic | E192: Azo Yellow Deep | F192: Yellow | G192: PY65 | H192: 1 | I192: Yes | J192: Semi Transparent | K192: ST | L192: Permanent | M192: I | N192: 2 | O192: Verified From Official Source
A193: PNT000143 | B193: Winsor And Newton | C193: Acrylic | D193: Professional Acrylic | E193: Buff Titanium | F193: White | G193: PBk11 | H193: 3 | I193: No | J193: Opaque | K193: O | L193: Extremely Permanent | M193: I | N193: 1 | O193: Verified From Official Source
A194: PNT000143 | B194: Winsor And Newton | C194: Acrylic | D194: Professional Acrylic | E194: Buff Titanium | F194: White | G194: PW6 | H194: 3 | I194: No | J194: Opaque | K194: O | L194: Extremely Permanent | M194: I | N194: 1 | O194: Verified From Official Source
A195: PNT000143 | B195: Winsor And Newton | C195: Acrylic | D195: Professional Acrylic | E195: Buff Titanium | F195: White | G195: PY42 | H195: 3 | I195: No | J195: Opaque | K195: O | L195: Extremely Permanent | M195: I | N195: 1 | O195: Verified From Official Source
A196: PNT000144 | B196: Winsor And Newton | C196: Acrylic | D196: Professional Acrylic | E196: Burnt Sienna | F196: Orange | G196: PR101 | H196: 1 | I196: Yes | J196: Transparent | K196: T | L196: Extremely Permanent | M196: I | N196: 1 | O196: Verified From Official Source
A197: PNT000145 | B197: Winsor And Newton | C197: Acrylic | D197: Professional Acrylic | E197: Burnt Umber | F197: Earth | G197: PBr7 | H197: 1 | I197: Yes | J197: Semi Opaque | K197: SO | L197: Extremely Permanent | M197: I | N197: 1 | O197: Verified From Official Source
A198: PNT000146 | B198: Winsor And Newton | C198: Acrylic | D198: Professional Acrylic | E198: Cadmium Lemon | F198: Yellow | G198: PY35 | H198: 1 | I198: Yes | J198: Opaque | K198: O | L198: Permanent | M198: I | N198: 3 | O198: Verified From Official Source
A199: PNT000147 | B199: Winsor And Newton | C199: Acrylic | D199: Professional Acrylic | E199: Cadmium Orange | F199: Orange | G199: PO20 | H199: 1 | I199: Yes | J199: Opaque | K199: O | L199: Permanent | M199: I | N199: 3 | O199: Verified From Official Source
A200: PNT000148 | B200: Winsor And Newton | C200: Acrylic | D200: Professional Acrylic | E200: Cadmium Red Deep | F200: Red | G200: PR108 | H200: 1 | I200: Yes | J200: Opaque | K200: O | L200: Permanent | M200: I | N200: 3 | O200: Verified From Official Source
A201: PNT000149 | B201: Winsor And Newton | C201: Acrylic | D201: Professional Acrylic | E201: CadRedMed | F201: Red | G201: Not Provided | H201: 0 | I201: Unknown | O201: Needs Review
A202: PNT000150 | B202: Winsor And Newton | C202: Acrylic | D202: Professional Acrylic | E202: Cadmium Red Light | F202: Red | G202: PR108 | H202: 1 | I202: Yes | J202: Opaque | K202: O | L202: Permanent | M202: I | N202: 3 | O202: Verified From Official Source
A203: PNT000151 | B203: Winsor And Newton | C203: Acrylic | D203: Professional Acrylic | E203: Cadmium Yellow Deep | F203: Yellow | G203: PO20 | H203: 2 | I203: No | J203: Opaque | K203: O | L203: Permanent | M203: I | N203: 3 | O203: Verified From Official Source
A204: PNT000151 | B204: Winsor And Newton | C204: Acrylic | D204: Professional Acrylic | E204: Cadmium Yellow Deep | F204: Yellow | G204: PY35 | H204: 2 | I204: No | J204: Opaque | K204: O | L204: Permanent | M204: I | N204: 3 | O204: Verified From Official Source
A205: PNT000152 | B205: Winsor And Newton | C205: Acrylic | D205: Professional Acrylic | E205: Cadmium Yellow Medium | F205: Yellow | G205: PY35 | H205: 1 | I205: Yes | J205: Opaque | K205: O | L205: Permanent | M205: I | N205: 3 | O205: Verified From Official Source
A206: PNT000153 | B206: Winsor And Newton | C206: Acrylic | D206: Professional Acrylic | E206: Cerulean Blue Chromium | F206: Blue | G206: PB36 | H206: 1 | I206: Yes | J206: Opaque | K206: O | L206: Extremely Permanent | M206: I | N206: 4 | O206: Verified From Official Source
A207: PNT000154 | B207: Winsor And Newton | C207: Acrylic | D207: Professional Acrylic | E207: Cerulean Blue | F207: Blue | G207: PB35 | H207: 1 | I207: Yes | J207: Opaque | K207: O | L207: Extremely Permanent | M207: I | N207: 5 | O207: Verified From Official Source
A208: PNT000155 | B208: Winsor And Newton | C208: Acrylic | D208: Professional Acrylic | E208: Chromium Oxide Green | F208: Green | G208: PG17 | H208: 1 | I208: Yes | J208: Opaque | K208: O | L208: Extremely Permanent | M208: I | N208: 3 | O208: Verified From Official Source
A209: PNT000156 | B209: Winsor And Newton | C209: Acrylic | D209: Professional Acrylic | E209: Cobalt Blue | F209: Blue | G209: PB28 | H209: 1 | I209: Yes | J209: Opaque | K209: O | L209: Extremely Permanent | M209: I | N209: 4 | O209: Verified From Official Source
A210: PNT000157 | B210: Winsor And Newton | C210: Acrylic | D210: Professional Acrylic | E210: Cobalt Blue Deep | F210: Blue | G210: PB73 | H210: 1 | I210: Yes | J210: Semi Opaque | K210: SO | L210: Extremely Permanent | M210: I | N210: 5 | O210: Verified From Official Source
A211: PNT000158 | B211: Winsor And Newton | C211: Acrylic | D211: Professional Acrylic | E211: Cobalt Green | F211: Blue | G211: PG50 | H211: 1 | I211: Yes | J211: Opaque | K211: O | L211: Extremely Permanent | M211: I | N211: 4 | O211: Verified From Official Source
A212: PNT000159 | B212: Winsor And Newton | C212: Acrylic | D212: Professional Acrylic | E212: Cobalt Green Deep | F212: Blue | G212: PG26 | H212: 1 | I212: Yes | J212: Semi Opaque | K212: SO | L212: Extremely Permanent | M212: I | N212: 3 | O212: Verified From Official Source
A213: PNT000160 | B213: Winsor And Newton | C213: Acrylic | D213: Professional Acrylic | E213: Cobalt Turquoise Light | F213: Blue | G213: PG50 | H213: 1 | I213: Yes | J213: Opaque | K213: O | L213: Extremely Permanent | M213: I | N213: 4 | O213: Verified From Official Source
...

Sheet Query_Dashboard
A1: ChromaCodex Database v3 - Query Dashboard
A3: Purpose | B3: Use this sheet as the entry point for filtering/querying the database without deleting any v2 relational tables.
A5: How to Query
B6: 1. Go to the Query_Source_View sheet.
B7: 2. Use the filter arrows in row 1 to filter by Brand, Medium, Product Line, Paint Name, RGB, Density, etc.
B8: 3. The source relational ID columns are included so every result can trace back to the underlying tables.
B9: 4. Do not type over ID columns. Add notes only in designated notes fields.
B10: 5. This v3 file preserves all v2 tabs and adds a safer query layer.
A13: Current Data Status
A14: Records imported
A15: Primary imported dataset | B15: Winsor And Newton Professional Acrylic from Sensual Logic import
A16: Pigment code status | B16: Mostly pending for this import because the source import did not provide pigment codes in v2
A17: Query readiness | B17: Filterable source view is active; dashboard formulas avoided to prevent Excel corruption
A21: Suggested Manual Filter Examples
B22: Brand_Name = Winsor And Newton
B23: Medium = Acrylic
B24: Product_Line_Name = Professional Acrylic
B25: Color_Family = Yellow
B26: Density greater than 1500
B27: RGB_Red greater than 200

Sheet Query_Source_View
A1: Paint_ID | B1: Record_ID | C1: Brand_ID | D1: Brand_Name | E1: Medium_ID | F1: Medium | G1: Product_Line_ID | H1: Product_Line_Name | I1: Product_Line_Type | J1: Paint_Name | K1: Paint_Product_Key | L1: Color_Family | M1: Pigment_ID | N1: Pigment_Code | O1: Pigment_Sequence | P1: Pigment_Count | Q1: Single_Pigment | R1: Transparency | S1: Opacity_Code | T1: Permanence | U1: ASTM_Rating | V1: WN_Series_Number | W1: Verification_Status | X1: Source_URL | Y1: Query_Include | Z1: Query_Match_Number
A2: PNT000001 | B2: 1 | C2: B001 | D2: Winsor And Newton | E2: M001 | F2: Oil | G2: PL001 | H2: Artists Oil | I2: Artist Oil | J2: Alizarin Crimson | K2: winsor and newton|oil|artists oil|alizarin crimson | L2: Red | M2: PIG000046 | N2: PR83 | O2: 1 | P2: 1 | Q2: Yes | S2: T | T2: B | W2: Needs Review | X2: https://sensuallogic.com/artistcolordata | Y2: =IF(AND(OR(Query_Interface!$B$5="All",$D2=Query_Interface!$B$5),OR(Query_Interface!$B$6="All",$F2=Query_Interface!$B$6),OR(Query_Interface!$B$7="All",$H2=Query_Interface!$B$7),OR(Query_Interface!$B$8="All",$N2=Query_Interface!$B$8),OR(Query_Interface!$B$9="All",$L2=Query_Interface!$B$9),OR(Query_Interface!$B$10="All",$R2=Query_Interface!$B$10),OR(Query_Interface!$B$11="All",$T2=Query_Interface!$B$11),OR(Query_Interface!$B$12="All",$Q2=Query_Interface!$B$12)),1,0) -> 1 | Z2: =IF($Y2=1,COUNTIF($Y$2:$Y2,1),"") -> 1
A3: PNT000002 | B3: 2 | C3: B001 | D3: Winsor And Newton | E3: M001 | F3: Oil | G3: PL001 | H3: Artists Oil | I3: Artist Oil | J3: Bismuth Yellow | K3: winsor and newton|oil|artists oil|bismuth yellow | L3: Yellow | M3: PIG000066 | N3: PY184 | O3: 1 | P3: 1 | Q3: Yes | S3: O | T3: A | W3: Needs Review | X3: https://sensuallogic.com/artistcolordata | Y3: =IF(AND(OR(Query_Interface!$B$5="All",$D3=Query_Interface!$B$5),OR(Query_Interface!$B$6="All",$F3=Query_Interface!$B$6),OR(Query_Interface!$B$7="All",$H3=Query_Interface!$B$7),OR(Query_Interface!$B$8="All",$N3=Query_Interface!$B$8),OR(Query_Interface!$B$9="All",$L3=Query_Interface!$B$9),OR(Query_Interface!$B$10="All",$R3=Query_Interface!$B$10),OR(Query_Interface!$B$11="All",$T3=Query_Interface!$B$11),OR(Query_Interface!$B$12="All",$Q3=Query_Interface!$B$12)),1,0) -> 1 | Z3: =IF($Y3=1,COUNTIF($Y$2:$Y3,1),"") -> 2
A4: PNT000003 | B4: 3 | C4: B001 | D4: Winsor And Newton | E4: M001 | F4: Oil | G4: PL001 | H4: Artists Oil | I4: Artist Oil | J4: Bright Red | K4: winsor and newton|oil|artists oil|bright red | L4: Red | M4: PIG000032 | N4: PR | O4: 1 | P4: 1 | Q4: Yes | S4: T | T4: A | W4: Needs Review | X4: https://sensuallogic.com/artistcolordata | Y4: =IF(AND(OR(Query_Interface!$B$5="All",$D4=Query_Interface!$B$5),OR(Query_Interface!$B$6="All",$F4=Query_Interface!$B$6),OR(Query_Interface!$B$7="All",$H4=Query_Interface!$B$7),OR(Query_Interface!$B$8="All",$N4=Query_Interface!$B$8),OR(Query_Interface!$B$9="All",$L4=Query_Interface!$B$9),OR(Query_Interface!$B$10="All",$R4=Query_Interface!$B$10),OR(Query_Interface!$B$11="All",$T4=Query_Interface!$B$11),OR(Query_Interface!$B$12="All",$Q4=Query_Interface!$B$12)),1,0) -> 1 | Z4: =IF($Y4=1,COUNTIF($Y$2:$Y4,1),"") -> 3
A5: PNT000004 | B5: 4 | C5: B001 | D5: Winsor And Newton | E5: M001 | F5: Oil | G5: PL001 | H5: Artists Oil | I5: Artist Oil | J5: Burnt Sienna | K5: winsor and newton|oil|artists oil|burnt sienna | L5: Orange | M5: PIG000033 | N5: PR101 | O5: 1 | P5: 1 | Q5: Yes | S5: T | T5: AA | W5: Needs Review | X5: https://sensuallogic.com/artistcolordata | Y5: =IF(AND(OR(Query_Interface!$B$5="All",$D5=Query_Interface!$B$5),OR(Query_Interface!$B$6="All",$F5=Query_Interface!$B$6),OR(Query_Interface!$B$7="All",$H5=Query_Interface!$B$7),OR(Query_Interface!$B$8="All",$N5=Query_Interface!$B$8),OR(Query_Interface!$B$9="All",$L5=Query_Interface!$B$9),OR(Query_Interface!$B$10="All",$R5=Query_Interface!$B$10),OR(Query_Interface!$B$11="All",$T5=Query_Interface!$B$11),OR(Query_Interface!$B$12="All",$Q5=Query_Interface!$B$12)),1,0) -> 1 | Z5: =IF($Y5=1,COUNTIF($Y$2:$Y5,1),"") -> 4
A6: PNT000005 | B6: 5 | C6: B001 | D6: Winsor And Newton | E6: M001 | F6: Oil | G6: PL001 | H6: Artists Oil | I6: Artist Oil | J6: Cadmium Lemon | K6: winsor and newton|oil|artists oil|cadmium lemon | L6: Yellow | M6: PIG000068 | N6: PY35 | O6: 1 | P6: 1 | Q6: Yes | S6: O | T6: A | W6: Needs Review | X6: https://sensuallogic.com/artistcolordata | Y6: =IF(AND(OR(Query_Interface!$B$5="All",$D6=Query_Interface!$B$5),OR(Query_Interface!$B$6="All",$F6=Query_Interface!$B$6),OR(Query_Interface!$B$7="All",$H6=Query_Interface!$B$7),OR(Query_Interface!$B$8="All",$N6=Query_Interface!$B$8),OR(Query_Interface!$B$9="All",$L6=Query_Interface!$B$9),OR(Query_Interface!$B$10="All",$R6=Query_Interface!$B$10),OR(Query_Interface!$B$11="All",$T6=Query_Interface!$B$11),OR(Query_Interface!$B$12="All",$Q6=Query_Interface!$B$12)),1,0) -> 1 | Z6: =IF($Y6=1,COUNTIF($Y$2:$Y6,1),"") -> 5
A7: PNT000006 | B7: 6 | C7: B001 | D7: Winsor And Newton | E7: M001 | F7: Oil | G7: PL001 | H7: Artists Oil | I7: Artist Oil | J7: Cadmium Red | K7: winsor and newton|oil|artists oil|cadmium red | L7: Red | M7: PIG000035 | N7: PR108 | O7: 1 | P7: 1 | Q7: Yes | S7: O | T7: A | W7: Needs Review | X7: https://sensuallogic.com/artistcolordata | Y7: =IF(AND(OR(Query_Interface!$B$5="All",$D7=Query_Interface!$B$5),OR(Query_Interface!$B$6="All",$F7=Query_Interface!$B$6),OR(Query_Interface!$B$7="All",$H7=Query_Interface!$B$7),OR(Query_Interface!$B$8="All",$N7=Query_Interface!$B$8),OR(Query_Interface!$B$9="All",$L7=Query_Interface!$B$9),OR(Query_Interface!$B$10="All",$R7=Query_Interface!$B$10),OR(Query_Interface!$B$11="All",$T7=Query_Interface!$B$11),OR(Query_Interface!$B$12="All",$Q7=Query_Interface!$B$12)),1,0) -> 1 | Z7: =IF($Y7=1,COUNTIF($Y$2:$Y7,1),"") -> 6
A8: PNT000007 | B8: 7 | C8: B001 | D8: Winsor And Newton | E8: M001 | F8: Oil | G8: PL001 | H8: Artists Oil | I8: Artist Oil | J8: Cadmium Yellow | K8: winsor and newton|oil|artists oil|cadmium yellow | L8: Yellow | M8: PIG000068 | N8: PY35 | O8: 1 | P8: 1 | Q8: Yes | S8: O | T8: A | W8: Needs Review | X8: https://sensuallogic.com/artistcolordata | Y8: =IF(AND(OR(Query_Interface!$B$5="All",$D8=Query_Interface!$B$5),OR(Query_Interface!$B$6="All",$F8=Query_Interface!$B$6),OR(Query_Interface!$B$7="All",$H8=Query_Interface!$B$7),OR(Query_Interface!$B$8="All",$N8=Query_Interface!$B$8),OR(Query_Interface!$B$9="All",$L8=Query_Interface!$B$9),OR(Query_Interface!$B$10="All",$R8=Query_Interface!$B$10),OR(Query_Interface!$B$11="All",$T8=Query_Interface!$B$11),OR(Query_Interface!$B$12="All",$Q8=Query_Interface!$B$12)),1,0) -> 1 | Z8: =IF($Y8=1,COUNTIF($Y$2:$Y8,1),"") -> 7
A9: PNT000008 | B9: 8 | C9: B001 | D9: Winsor And Newton | E9: M001 | F9: Oil | G9: PL001 | H9: Artists Oil | I9: Artist Oil | J9: Cadmium Yellow Deep | K9: winsor and newton|oil|artists oil|cadmium yellow deep | L9: Yellow | M9: PIG000028 | N9: PO20 | O9: 1 | P9: 2 | Q9: No | S9: O | T9: A | W9: Needs Review | X9: https://sensuallogic.com/artistcolordata | Y9: =IF(AND(OR(Query_Interface!$B$5="All",$D9=Query_Interface!$B$5),OR(Query_Interface!$B$6="All",$F9=Query_Interface!$B$6),OR(Query_Interface!$B$7="All",$H9=Query_Interface!$B$7),OR(Query_Interface!$B$8="All",$N9=Query_Interface!$B$8),OR(Query_Interface!$B$9="All",$L9=Query_Interface!$B$9),OR(Query_Interface!$B$10="All",$R9=Query_Interface!$B$10),OR(Query_Interface!$B$11="All",$T9=Query_Interface!$B$11),OR(Query_Interface!$B$12="All",$Q9=Query_Interface!$B$12)),1,0) -> 1 | Z9: =IF($Y9=1,COUNTIF($Y$2:$Y9,1),"") -> 8
A10: PNT000008 | B10: 8 | C10: B001 | D10: Winsor And Newton | E10: M001 | F10: Oil | G10: PL001 | H10: Artists Oil | I10: Artist Oil | J10: Cadmium Yellow Deep | K10: winsor and newton|oil|artists oil|cadmium yellow deep | L10: Yellow | M10: PIG000068 | N10: PY35 | O10: 2 | P10: 2 | Q10: No | S10: O | T10: A | W10: Needs Review | X10: https://sensuallogic.com/artistcolordata | Y10: =IF(AND(OR(Query_Interface!$B$5="All",$D10=Query_Interface!$B$5),OR(Query_Interface!$B$6="All",$F10=Query_Interface!$B$6),OR(Query_Interface!$B$7="All",$H10=Query_Interface!$B$7),OR(Query_Interface!$B$8="All",$N10=Query_Interface!$B$8),OR(Query_Interface!$B$9="All",$L10=Query_Interface!$B$9),OR(Query_Interface!$B$10="All",$R10=Query_Interface!$B$10),OR(Query_Interface!$B$11="All",$T10=Query_Interface!$B$11),OR(Query_Interface!$B$12="All",$Q10=Query_Interface!$B$12)),1,0) -> 1 | Z10: =IF($Y10=1,COUNTIF($Y$2:$Y10,1),"") -> 9
A11: PNT000009 | B11: 9 | C11: B001 | D11: Winsor And Newton | E11: M001 | F11: Oil | G11: PL001 | H11: Artists Oil | I11: Artist Oil | J11: Cerulean Blue | K11: winsor and newton|oil|artists oil|cerulean blue | L11: Blue | M11: PIG000008 | N11: PB35 | O11: 1 | P11: 1 | Q11: Yes | S11: SO | T11: AA | W11: Needs Review | X11: https://sensuallogic.com/artistcolordata | Y11: =IF(AND(OR(Query_Interface!$B$5="All",$D11=Query_Interface!$B$5),OR(Query_Interface!$B$6="All",$F11=Query_Interface!$B$6),OR(Query_Interface!$B$7="All",$H11=Query_Interface!$B$7),OR(Query_Interface!$B$8="All",$N11=Query_Interface!$B$8),OR(Query_Interface!$B$9="All",$L11=Query_Interface!$B$9),OR(Query_Interface!$B$10="All",$R11=Query_Interface!$B$10),OR(Query_Interface!$B$11="All",$T11=Query_Interface!$B$11),OR(Query_Interface!$B$12="All",$Q11=Query_Interface!$B$12)),1,0) -> 1 | Z11: =IF($Y11=1,COUNTIF($Y$2:$Y11,1),"") -> 10
A12: PNT000010 | B12: 10 | C12: B001 | D12: Winsor And Newton | E12: M001 | F12: Oil | G12: PL001 | H12: Artists Oil | I12: Artist Oil | J12: Cobalt Blue | K12: winsor and newton|oil|artists oil|cobalt blue | L12: Blue | M12: PIG000006 | N12: PB28 | O12: 1 | P12: 1 | Q12: Yes | S12: ST | T12: AA | W12: Needs Review | X12: https://sensuallogic.com/artistcolordata | Y12: =IF(AND(OR(Query_Interface!$B$5="All",$D12=Query_Interface!$B$5),OR(Query_Interface!$B$6="All",$F12=Query_Interface!$B$6),OR(Query_Interface!$B$7="All",$H12=Query_Interface!$B$7),OR(Query_Interface!$B$8="All",$N12=Query_Interface!$B$8),OR(Query_Interface!$B$9="All",$L12=Query_Interface!$B$9),OR(Query_Interface!$B$10="All",$R12=Query_Interface!$B$10),OR(Query_Interface!$B$11="All",$T12=Query_Interface!$B$11),OR(Query_Interface!$B$12="All",$Q12=Query_Interface!$B$12)),1,0) -> 1 | Z12: =IF($Y12=1,COUNTIF($Y$2:$Y12,1),"") -> 11
A13: PNT000011 | B13: 11 | C13: B001 | D13: Winsor And Newton | E13: M001 | F13: Oil | G13: PL001 | H13: Artists Oil | I13: Artist Oil | J13: Cobalt Blue Deep | K13: winsor and newton|oil|artists oil|cobalt blue deep | L13: Blue | M13: PIG000011 | N13: PB74 | O13: 1 | P13: 1 | Q13: Yes | S13: ST | T13: AA | W13: Needs Review | X13: https://sensuallogic.com/artistcolordata | Y13: =IF(AND(OR(Query_Interface!$B$5="All",$D13=Query_Interface!$B$5),OR(Query_Interface!$B$6="All",$F13=Query_Interface!$B$6),OR(Query_Interface!$B$7="All",$H13=Query_Interface!$B$7),OR(Query_Interface!$B$8="All",$N13=Query_Interface!$B$8),OR(Query_Interface!$B$9="All",$L13=Query_Interface!$B$9),OR(Query_Interface!$B$10="All",$R13=Query_Interface!$B$10),OR(Query_Interface!$B$11="All",$T13=Query_Interface!$B$11),OR(Query_Interface!$B$12="All",$Q13=Query_Interface!$B$12)),1,0) -> 1 | Z13: =IF($Y13=1,COUNTIF($Y$2:$Y13,1),"") -> 12
... A186: PNT000139 | B186: 139 | C186: B001 | D186: Winsor And Newton | E186: M003 | F186: Acrylic | G186: PL003 | H186: Galeria Acrylic | I186: Student Acrylic | J186: Yellow Ochre | K186: winsor and newton|acrylic|galeria acrylic|yellow ochre | L186: Yellow | M186: PIG000013 | N186: PBk11 | O186: 3 | P186: 3 | Q186: No | S186: O | T186: AA | W186: Needs Review | X186: https://sensuallogic.com/artistcolordata | Y186: =IF(AND(OR(Query_Interface!$B$5="All",$D186=Query_Interface!$B$5),OR(Query_Interface!$B$6="All",$F186=Query_Interface!$B$6),OR(Query_Interface!$B$7="All",$H186=Query_Interface!$B$7),OR(Query_Interface!$B$8="All",$N186=Query_Interface!$B$8),OR(Query_Interface!$B$9="All",$L186=Query_Interface!$B$9),OR(Query_Interface!$B$10="All",$R186=Query_Interface!$B$10),OR(Query_Interface!$B$11="All",$T186=Query_Interface!$B$11),OR(Query_Interface!$B$12="All",$Q186=Query_Interface!$B$12)),1,0) -> 1 | Z186: =IF($Y186=1,COUNTIF($Y$2:$Y186,1),"") -> 185
A187: PNT000140 | B187: 140 | C187: B001 | D187: Winsor And Newton | E187: M003 | F187: Acrylic | G187: PL004 | H187: Professional Acrylic | I187: Artist Acrylic | J187: Azo Yellow Medium | K187: winsor and newton|acrylic|professional acrylic|azo yellow medium | L187: Yellow | M187: PIG000074 | N187: PY74 | O187: 1 | P187: 1 | Q187: Yes | R187: Semi Opaque | S187: SO | T187: Permanent | U187: I | V187: 2 | W187: Verified From Official Source | X187: https://www.winsornewton.com/pages/professional-acrylic-colour | Y187: =IF(AND(OR(Query_Interface!$B$5="All",$D187=Query_Interface!$B$5),OR(Query_Interface!$B$6="All",$F187=Query_Interface!$B$6),OR(Query_Interface!$B$7="All",$H187=Query_Interface!$B$7),OR(Query_Interface!$B$8="All",$N187=Query_Interface!$B$8),OR(Query_Interface!$B$9="All",$L187=Query_Interface!$B$9),OR(Query_Interface!$B$10="All",$R187=Query_Interface!$B$10),OR(Query_Interface!$B$11="All",$T187=Query_Interface!$B$11),OR(Query_Interface!$B$12="All",$Q187=Query_Interface!$B$12)),1,0) -> 1 | Z187: =IF($Y187=1,COUNTIF($Y$2:$Y187,1),"") -> 186
A188: PNT000141 | B188: 141 | C188: B001 | D188: Winsor And Newton | E188: M003 | F188: Acrylic | G188: PL004 | H188: Professional Acrylic | I188: Artist Acrylic | J188: Bismuth Yellow | K188: winsor and newton|acrylic|professional acrylic|bismuth yellow | L188: Yellow | M188: PIG000066 | N188: PY184 | O188: 1 | P188: 1 | Q188: Yes | R188: Opaque | S188: O | T188: Permanent | U188: I | V188: 4 | W188: Verified From Official Source | X188: https://www.winsornewton.com/pages/professional-acrylic-colour | Y188: =IF(AND(OR(Query_Interface!$B$5="All",$D188=Query_Interface!$B$5),OR(Query_Interface!$B$6="All",$F188=Query_Interface!$B$6),OR(Query_Interface!$B$7="All",$H188=Query_Interface!$B$7),OR(Query_Interface!$B$8="All",$N188=Query_Interface!$B$8),OR(Query_Interface!$B$9="All",$L188=Query_Interface!$B$9),OR(Query_Interface!$B$10="All",$R188=Query_Interface!$B$10),OR(Query_Interface!$B$11="All",$T188=Query_Interface!$B$11),OR(Query_Interface!$B$12="All",$Q188=Query_Interface!$B$12)),1,0) -> 1 | Z188: =IF($Y188=1,COUNTIF($Y$2:$Y188,1),"") -> 187
A189: PNT000142 | B189: 142 | C189: B001 | D189: Winsor And Newton | E189: M003 | F189: Acrylic | G189: PL004 | H189: Professional Acrylic | I189: Artist Acrylic | J189: Azo Yellow Deep | K189: winsor and newton|acrylic|professional acrylic|azo yellow deep | L189: Yellow | M189: PIG000072 | N189: PY65 | O189: 1 | P189: 1 | Q189: Yes | R189: Semi Transparent | S189: ST | T189: Permanent | U189: I | V189: 2 | W189: Verified From Official Source | X189: https://www.winsornewton.com/pages/professional-acrylic-colour | Y189: =IF(AND(OR(Query_Interface!$B$5="All",$D189=Query_Interface!$B$5),OR(Query_Interface!$B$6="All",$F189=Query_Interface!$B$6),OR(Query_Interface!$B$7="All",$H189=Query_Interface!$B$7),OR(Query_Interface!$B$8="All",$N189=Query_Interface!$B$8),OR(Query_Interface!$B$9="All",$L189=Query_Interface!$B$9),OR(Query_Interface!$B$10="All",$R189=Query_Interface!$B$10),OR(Query_Interface!$B$11="All",$T189=Query_Interface!$B$11),OR(Query_Interface!$B$12="All",$Q189=Query_Interface!$B$12)),1,0) -> 1 | Z189: =IF($Y189=1,COUNTIF($Y$2:$Y189,1),"") -> 188
A190: PNT000143 | B190: 143 | C190: B001 | D190: Winsor And Newton | E190: M003 | F190: Acrylic | G190: PL004 | H190: Professional Acrylic | I190: Artist Acrylic | J190: Buff Titanium | K190: winsor and newton|acrylic|professional acrylic|buff titanium | L190: White | M190: PIG000013 | N190: PBk11 | O190: 1 | P190: 3 | Q190: No | R190: Opaque | S190: O | T190: Extremely Permanent | U190: I | V190: 1 | W190: Verified From Official Source | X190: https://www.winsornewton.com/pages/professional-acrylic-colour | Y190: =IF(AND(OR(Query_Interface!$B$5="All",$D190=Query_Interface!$B$5),OR(Query_Interface!$B$6="All",$F190=Query_Interface!$B$6),OR(Query_Interface!$B$7="All",$H190=Query_Interface!$B$7),OR(Query_Interface!$B$8="All",$N190=Query_Interface!$B$8),OR(Query_Interface!$B$9="All",$L190=Query_Interface!$B$9),OR(Query_Interface!$B$10="All",$R190=Query_Interface!$B$10),OR(Query_Interface!$B$11="All",$T190=Query_Interface!$B$11),OR(Query_Interface!$B$12="All",$Q190=Query_Interface!$B$12)),1,0) -> 1 | Z190: =IF($Y190=1,COUNTIF($Y$2:$Y190,1),"") -> 189
A191: PNT000143 | B191: 143 | C191: B001 | D191: Winsor And Newton | E191: M003 | F191: Acrylic | G191: PL004 | H191: Professional Acrylic | I191: Artist Acrylic | J191: Buff Titanium | K191: winsor and newton|acrylic|professional acrylic|buff titanium | L191: White | M191: PIG000058 | N191: PW6 | O191: 2 | P191: 3 | Q191: No | R191: Opaque | S191: O | T191: Extremely Permanent | U191: I | V191: 1 | W191: Verified From Official Source | X191: https://www.winsornewton.com/pages/professional-acrylic-colour | Y191: =IF(AND(OR(Query_Interface!$B$5="All",$D191=Query_Interface!$B$5),OR(Query_Interface!$B$6="All",$F191=Query_Interface!$B$6),OR(Query_Interface!$B$7="All",$H191=Query_Interface!$B$7),OR(Query_Interface!$B$8="All",$N191=Query_Interface!$B$8),OR(Query_Interface!$B$9="All",$L191=Query_Interface!$B$9),OR(Query_Interface!$B$10="All",$R191=Query_Interface!$B$10),OR(Query_Interface!$B$11="All",$T191=Query_Interface!$B$11),OR(Query_Interface!$B$12="All",$Q191=Query_Interface!$B$12)),1,0) -> 1 | Z191: =IF($Y191=1,COUNTIF($Y$2:$Y191,1),"") -> 190
A192: PNT000143 | B192: 143 | C192: B001 | D192: Winsor And Newton | E192: M003 | F192: Acrylic | G192: PL004 | H192: Professional Acrylic | I192: Artist Acrylic | J192: Buff Titanium | K192: winsor and newton|acrylic|professional acrylic|buff titanium | L192: White | M192: PIG000069 | N192: PY42 | O192: 3 | P192: 3 | Q192: No | R192: Opaque | S192: O | T192: Extremely Permanent | U192: I | V192: 1 | W192: Verified From Official Source | X192: https://www.winsornewton.com/pages/professional-acrylic-colour | Y192: =IF(AND(OR(Query_Interface!$B$5="All",$D192=Query_Interface!$B$5),OR(Query_Interface!$B$6="All",$F192=Query_Interface!$B$6),OR(Query_Interface!$B$7="All",$H192=Query_Interface!$B$7),OR(Query_Interface!$B$8="All",$N192=Query_Interface!$B$8),OR(Query_Interface!$B$9="All",$L192=Query_Interface!$B$9),OR(Query_Interface!$B$10="All",$R192=Query_Interface!$B$10),OR(Query_Interface!$B$11="All",$T192=Query_Interface!$B$11),OR(Query_Interface!$B$12="All",$Q192=Query_Interface!$B$12)),1,0) -> 1 | Z192: =IF($Y192=1,COUNTIF($Y$2:$Y192,1),"") -> 191
A193: PNT000144 | B193: 144 | C193: B001 | D193: Winsor And Newton | E193: M003 | F193: Acrylic | G193: PL004 | H193: Professional Acrylic | I193: Artist Acrylic | J193: Burnt Sienna | K193: winsor and newton|acrylic|professional acrylic|burnt sienna | L193: Orange | M193: PIG000033 | N193: PR101 | O193: 1 | P193: 1 | Q193: Yes | R193: Transparent | S193: T | T193: Extremely Permanent | U193: I | V193: 1 | W193: Verified From Official Source | X193: https://www.winsornewton.com/pages/professional-acrylic-colour | Y193: =IF(AND(OR(Query_Interface!$B$5="All",$D193=Query_Interface!$B$5),OR(Query_Interface!$B$6="All",$F193=Query_Interface!$B$6),OR(Query_Interface!$B$7="All",$H193=Query_Interface!$B$7),OR(Query_Interface!$B$8="All",$N193=Query_Interface!$B$8),OR(Query_Interface!$B$9="All",$L193=Query_Interface!$B$9),OR(Query_Interface!$B$10="All",$R193=Query_Interface!$B$10),OR(Query_Interface!$B$11="All",$T193=Query_Interface!$B$11),OR(Query_Interface!$B$12="All",$Q193=Query_Interface!$B$12)),1,0) -> 1 | Z193: =IF($Y193=1,COUNTIF($Y$2:$Y193,1),"") -> 192
A194: PNT000145 | B194: 145 | C194: B001 | D194: Winsor And Newton | E194: M003 | F194: Acrylic | G194: PL004 | H194: Professional Acrylic | I194: Artist Acrylic | J194: Burnt Umber | K194: winsor and newton|acrylic|professional acrylic|burnt umber | L194: Earth | M194: PIG000020 | N194: PBr7 | O194: 1 | P194: 1 | Q194: Yes | R194: Semi Opaque | S194: SO | T194: Extremely Permanent | U194: I | V194: 1 | W194: Verified From Official Source | X194: https://www.winsornewton.com/pages/professional-acrylic-colour | Y194: =IF(AND(OR(Query_Interface!$B$5="All",$D194=Query_Interface!$B$5),OR(Query_Interface!$B$6="All",$F194=Query_Interface!$B$6),OR(Query_Interface!$B$7="All",$H194=Query_Interface!$B$7),OR(Query_Interface!$B$8="All",$N194=Query_Interface!$B$8),OR(Query_Interface!$B$9="All",$L194=Query_Interface!$B$9),OR(Query_Interface!$B$10="All",$R194=Query_Interface!$B$10),OR(Query_Interface!$B$11="All",$T194=Query_Interface!$B$11),OR(Query_Interface!$B$12="All",$Q194=Query_Interface!$B$12)),1,0) -> 1 | Z194: =IF($Y194=1,COUNTIF($Y$2:$Y194,1),"") -> 193
A195: PNT000146 | B195: 146 | C195: B001 | D195: Winsor And Newton | E195: M003 | F195: Acrylic | G195: PL004 | H195: Professional Acrylic | I195: Artist Acrylic | J195: Cadmium Lemon | K195: winsor and newton|acrylic|professional acrylic|cadmium lemon | L195: Yellow | M195: PIG000068 | N195: PY35 | O195: 1 | P195: 1 | Q195: Yes | R195: Opaque | S195: O | T195: Permanent | U195: I | V195: 3 | W195: Verified From Official Source | X195: https://www.winsornewton.com/pages/professional-acrylic-colour | Y195: =IF(AND(OR(Query_Interface!$B$5="All",$D195=Query_Interface!$B$5),OR(Query_Interface!$B$6="All",$F195=Query_Interface!$B$6),OR(Query_Interface!$B$7="All",$H195=Query_Interface!$B$7),OR(Query_Interface!$B$8="All",$N195=Query_Interface!$B$8),OR(Query_Interface!$B$9="All",$L195=Query_Interface!$B$9),OR(Query_Interface!$B$10="All",$R195=Query_Interface!$B$10),OR(Query_Interface!$B$11="All",$T195=Query_Interface!$B$11),OR(Query_Interface!$B$12="All",$Q195=Query_Interface!$B$12)),1,0) -> 1 | Z195: =IF($Y195=1,COUNTIF($Y$2:$Y195,1),"") -> 194
A196: PNT000147 | B196: 147 | C196: B001 | D196: Winsor And Newton | E196: M003 | F196: Acrylic | G196: PL004 | H196: Professional Acrylic | I196: Artist Acrylic | J196: Cadmium Orange | K196: winsor and newton|acrylic|professional acrylic|cadmium orange | L196: Orange | M196: PIG000028 | N196: PO20 | O196: 1 | P196: 1 | Q196: Yes | R196: Opaque | S196: O | T196: Permanent | U196: I | V196: 3 | W196: Verified From Official Source | X196: https://www.winsornewton.com/pages/professional-acrylic-colour | Y196: =IF(AND(OR(Query_Interface!$B$5="All",$D196=Query_Interface!$B$5),OR(Query_Interface!$B$6="All",$F196=Query_Interface!$B$6),OR(Query_Interface!$B$7="All",$H196=Query_Interface!$B$7),OR(Query_Interface!$B$8="All",$N196=Query_Interface!$B$8),OR(Query_Interface!$B$9="All",$L196=Query_Interface!$B$9),OR(Query_Interface!$B$10="All",$R196=Query_Interface!$B$10),OR(Query_Interface!$B$11="All",$T196=Query_Interface!$B$11),OR(Query_Interface!$B$12="All",$Q196=Query_Interface!$B$12)),1,0) -> 1 | Z196: =IF($Y196=1,COUNTIF($Y$2:$Y196,1),"") -> 195
